Workbook
Name Lookup_Choices: [1]SOP!$H$1:$H$6
Name Lookup_Choices: '[2]Leadership 1 '!$H$1:$H$6
Name Lookup_Table: [1]SOP!$H$1:$I$6
Name Lookup_Table: '[2]Leadership 1 '!$H$1:$I$6

Sheet Cover
B7: Cyber Security Assurance Framework
B8: Maturity Assessment-NALCO
F9: Dated: 10.06.2024
I10: Version 2.0
B13: National Aluminium Company Limited (NALCO) is a Schedule ‘A’ Navratna CPSE established on 7th January, 1981 , 2022 NALCO India , A Govt. of India Enterprise
E18: `

Sheet Index
A1: S. No. | B1: Particular | C1: Link
A2: 1 | B2: Read Me | C2: Click Here
A3: 2 | B3: Maturity of Security Domains | C3: Click Here
A4: 3 | B4: Detailed Observations | C4: Click Here

Sheet Read Me
A1: Objective:
A2: The objective of this Workbook is to provide an assurance framework for the cyber security maturity assessment
A4: Domains Covered:
A5: This workbook lists a database of controls against 19 security domains identified for the organization's environment. It may be noted that there may be few controls/ security domains which might not be applicable to a particular organization. The workbook provides ready to use templates which will calculate the control rating of the individual controls and provides an overall domain rating for the respective security domain.
A7: Approach:
A8: This workbook lists a database of controls against 19 security domains identified for the organizations environment. It may be noted that there may be few controls/ security domains which might not be applicable to a particular organization. The workbook provides ready to use templates which will calculate the control rating of the individual controls and provides an overall domain rating for the respective security domain.
A9: 1. Identification of Cyber Security domains defined under Security Domains Tab.
A10: 2. Identification of sub domains under each security domain and covering the controls in the sub domain.
A11: 3. Identification of controls as Preventive, Detective, Corrective controls.
A12: 4. The Key controls are identified within each sub domain and they are given additional 20% more weightage than other controls.
A13: 5. The ratings given against each control is divided among four sections which are Documentation, Implementation, Automation and Monitoring & Review.
A21: 6. Based on each control rating, sub domain rating will be derived followed by Security Domain Maturity Rating aligned to CMMI and NIST.
... A24: Definitions for Risk Criticality:
A25: Risk Rating | B25: Definition | C25: Control rating
A26: High | B26: Observations having direct impact on Impact on CIA, financial/operational data | C26: below 1.74
A27: Medium | B27: Observations having impact on the design and system level controls of the organization | C27: 1.75-2.29
A28: Low | B28: Observations that do not have direct impact on the organizations data, design and system level controls | C28: 2.30-2.74
A29: Information | B29: opportunity for improvement | C29: 2.75-2.99
A30: Note: These control rating are only for guidance purpose.
A32: Version Control:
A33: Version No | B33: Description of changes made
A34: 1 | B34: Initial Version
A35: 2 | B35: Added controls as mentioned below: IS Governance: 1.9; Access Management: 2.5, 2.13, 2.16, 2.24, 2.32, 2.33; Asset Management: 3.4, 3.21, 3.22; Incident Management: 4.19; Infra and Operations Sec: 5.11, 5.12, 5.22, 5.37, 5.40, 5.46, 5.47, 5.48, 5.73, 5.83, 5.84, 5.85, 5.88, 5.89, 5.90, 5.91, 5.92, 5.93; Mobility: 6.8, 6.12, 6.23; Privacy: 7.9, 7.10, 7.11; Cloud: 8.4, 8.5, 8.6, 8.7, 8.8, 8.9, 8.10, 8.14, 8.19, 8.24, 8.25, 8.26, 8.33; Network Security: 10.15, 10.17, 10.19, 10.29, 10.30, 10.43, 10.72, 10.75, 10.76, 10.77, 10.78, 10.83, 10.84, 10.85, 10.86, 10.87, 10.88, 10.89, 10.90, 10.91; Endpoint Security: 11.10, 11.13, 11.14, 11.15, 11.17, 11.22, 11.23, 11.24, 11.25, 11.26, 11.27, 11.28, 11.29, 11.30, 11.31, 11.32, 11.33, 11.34, 11.35, 11.36, 11.37, 11.38, 11.39, 11.40, 11.41, 11.42, 11.43, 11.44; Application Security: 13.1, 13.2, 13.3, 13.19, 13.19, 13.22, 13.32, 13.34, 13.44; Encryption: 14.14, 14.15, 14.16, 14.7, 14.18, 14.19; Risk Management: 15.4, 15.8, 15.15; Business Continuity: 16.19, 16.20; Physical and Environment: 17.21, 17.25; Third Party: 18.7, 18.15, 18.16, 18.17, 18.18, 18.19, 18.20, 18.21, 18.26, 18.27

Sheet Security Domains
A1: S. No. | B1: Domain | C1: Maturity Rating | D1: Maturity Rating Category
A2: 1 | B2: IS Governance | C2: ='IS Governance'!F1 -> 3.2222222 | D2: ='IS Governance'!E1 -> Defined
A3: 2 | B3: Access Management | C3: ='Access Management'!F1 -> 2.6837963 | D3: ='Access Management'!E1 -> Partial
A4: 3 | B4: Asset Management | C4: ='Asset Management'!F1 -> 2.7732564 | D4: ='Asset Management'!E1 -> Partial
A5: 4 | B5: Incident Management | C5: ='Incident Management'!F1 -> 4.7861111 | D5: ='Incident Management'!E1 -> Repeatable
A6: 5 | B6: Infrastructure & Operations Security | C6: ='Infra and Operations Sec'!F1 -> 2.5062484 | D6: ='Infra and Operations Sec'!E1 -> Partial
A7: 6 | B7: Emerging Technologies | C7: ='Emerging Technology'!F1 -> 4.3279672 | D7: ='Emerging Technology'!E1 -> Repeatable
A8: 7 | B8: Network Security | C8: ='Network Security'!F1 -> 2.9475565 | D8: ='Network Security'!E1 -> Partial
A9: 8 | B9: Endpoint Protection | C9: ='Endpoint Protection'!F1 -> 3.0547543 | D9: ='Endpoint Protection'!E1 -> Defined
A10: 9 | B10: Application Security | C10: ='Application Security'!F1 -> 4.1188776 | D10: ='Application Security'!E1 -> Repeatable
A11: 10 | B11: Risk Management | C11: ='Risk Management'!F1 -> 3.9027778 | D11: ='Risk Management'!E1 -> Defined
A12: 11 | B12: Human Resource Security | C12: ='Human Resource Security'!F1 -> 4.5555556 | D12: ='Human Resource Security'!E1 -> Repeatable
A13: 12 | B13: Business Continuity | C13: ='Business Continuity'!F1 -> 3.615812 | D13: ='Business Continuity'!E1 -> Defined
A14: 13 | B14: Physical & Environmental Security | C14: ='Physical and Environment'!F1 -> 3.9193122 | D14: ='Physical and Environment'!E1 -> Defined
A15: 14 | B15: Third Party Security | C15: ='Third Party'!F1 -> 3.931652 | D15: ='Third Party'!E1 -> Defined
A16: 15 | B16: Compliance Management | C16: ='Compliance management'!F1 -> 3.2819444 | D16: ='Compliance management'!E1 -> Defined
B18: Overall Rating | C18: =AVERAGE(C2:C16) -> 3.5751896 | D18: =IF(C18="NA","Not Applicable",VLOOKUP(C19,'Maturity Rating'!G4:H8,2,FALSE)) -> Defined
C19: =ROUNDDOWN(C18,0) -> 3
E20: =ROUND(C18,0) -> 4
B21: Excluded Privacy | C21: =(SUM(C2:C16)-#REF!)/16 -> #REF!

Sheet IS Governance
C1: Average Domain Rating | E1: =IF(F1="NA","Not Applicable",VLOOKUP(T1,'Maturity Rating'!G4:H8,2,FALSE)) -> Defined | F1: =IF(U1="NANANA","NA",AVERAGE(N4:N20)) -> 3.2222222 | T1: =ROUNDDOWN(F1,0) -> 3 | U1: =CONCATENATE(N4,N10,N17) -> 53.666666666666671
A3: S. No. | B3: High Level Description | C3: Control Description | D3: Identified Key Controls (K) | E3: Control | F3: Preventive/ Detective/Corrective | G3: Documentation | H3: Implementation | I3: Automation | J3: Monitor & Review | K3: Control Rating | L3: Rating with Key controls weightage | M3: Average Rating | N3: Maturity Rating (1 - 5) | O3: Category | S3: Doc | T3: Impl | U3: Auto | V3: Review
A4: 1.1 | B4: Policy and procedures | C4: Information Security policy should be established, documented and approved by authorized individuals. The document should be reviewed periodically and updated whenever significant changes occur. | D4: K | E4: Organization should have an Information Security policy defined, approved by the management | F4: Preventive | G4: Formally Documented | H4: 51 - 100% Implemented | I4: Automated | J4: Monitored & Reviewed | K4: =IF(W4="NANANANA",S4,IF(AND(OR(G4="Formally Documented",G4="Informally Documented"),H4="Not Implemented"),0.5*AVERAGE(S4:V4),AVERAGE(S4:V4))) -> 3 | L4: =IF(AND(D4="K",K4=1),'Maturity Rating'!$E$8,IF(K4="NA",K4,IF(D4="K",K4*'Maturity Rating'!$E$7,K4))) -> 3.6 | M4: =IF(X4="NANANANA",K4,AVERAGE(L4:L9)) -> 3.0583333 | N4: =IF(M4<1.1,1,IF(M4="NA",M4,(MIN(5,M4/3*5)))) -> 5 | O4: =IF(N4="NA",N4,VLOOKUP(Q4,'Maturity Rating'!G4:H8,2,FALSE)) -> Adaptive | Q4: =IF(N4="NA",N4,ROUNDDOWN(N4,0)) -> 5 | S4: =VLOOKUP(G4,'Maturity Rating'!A$2:B$5,2,FALSE) -> 3 | T4: =VLOOKUP(H4,'Maturity Rating'!A$8:B$11,2,FALSE) -> 3 | U4: =VLOOKUP(I4,'Maturity Rating'!A$14:B$17,2,FALSE) -> 3 | V4: =VLOOKUP(J4,'Maturity Rating'!A$20:B$23,2,FALSE) -> 3 | W4: =CONCATENATE(S4,T4,U4,V4) -> 3333 | X4: =CONCATENATE(L4,L5,L6,L9) -> 3.632.753
A5: 1.2 | E5: The documents are reviewed, updated and approved as per the defined frequency in the policy/ procedure. | F5: Preventive | G5: Formally Documented | H5: 51 - 100% Implemented | I5: Automated | J5: Monitored & Reviewed | K5: =IF(W5="NANANANA",S5,IF(AND(OR(G5="Formally Documented",G5="Informally Documented"),H5="Not Implemented"),0.5*AVERAGE(S5:V5),AVERAGE(S5:V5))) -> 3 | L5: =IF(AND(D5="K",K5=1),'Maturity Rating'!$E$8,IF(K5="NA",K5,IF(D5="K",K5*'Maturity Rating'!$E$7,K5))) -> 3 | S5: =VLOOKUP(G5,'Maturity Rating'!A$2:B$5,2,FALSE) -> 3 | T5: =VLOOKUP(H5,'Maturity Rating'!A$8:B$11,2,FALSE) -> 3 | U5: =VLOOKUP(I5,'Maturity Rating'!A$14:B$17,2,FALSE) -> 3 | V5: =VLOOKUP(J5,'Maturity Rating'!A$20:B$23,2,FALSE) -> 3 | W5: =CONCATENATE(S5,T5,U5,V5) -> 3333
A6: 1.3 | E6: The Information Security policy covers objectives, scope, ownership and responsibility for the policy. | F6: Preventive | G6: Formally Documented | H6: 51 - 100% Implemented | I6: Automated | J6: Partially Monitored & Reviewed | K6: =IF(W6="NANANANA",S6,IF(AND(OR(G6="Formally Documented",G6="Informally Documented"),H6="Not Implemented"),0.5*AVERAGE(S6:V6),AVERAGE(S6:V6))) -> 2.75 | L6: =IF(AND(D6="K",K6=1),'Maturity Rating'!$E$8,IF(K6="NA",K6,IF(D6="K",K6*'Maturity Rating'!$E$7,K6))) -> 2.75 | S6: =VLOOKUP(G6,'Maturity Rating'!A$2:B$5,2,FALSE) -> 3 | T6: =VLOOKUP(H6,'Maturity Rating'!A$8:B$11,2,FALSE) -> 3 | U6: =VLOOKUP(I6,'Maturity Rating'!A$14:B$17,2,FALSE) -> 3 | V6: =VLOOKUP(J6,'Maturity Rating'!A$20:B$23,2,FALSE) -> 2 | W6: =CONCATENATE(S6,T6,U6,V6) -> 3332
A7: 1.4 | E7: The IS organization structure should be well defined, reviewed and approved by the management. | F7: Preventive | G7: Formally Documented | H7: 51 - 100% Implemented | I7: Automated | J7: Monitored & Reviewed | K7: =IF(W7="NANANANA",S7,IF(AND(OR(G7="Formally Documented",G7="Informally Documented"),H7="Not Implemented"),0.5*AVERAGE(S7:V7),AVERAGE(S7:V7))) -> 3 | L7: =IF(AND(D7="K",K7=1),'Maturity Rating'!$E$8,IF(K7="NA",K7,IF(D7="K",K7*'Maturity Rating'!$E$7,K7))) -> 3 | S7: =VLOOKUP(G7,'Maturity Rating'!A$2:B$5,2,FALSE) -> 3 | T7: =VLOOKUP(H7,'Maturity Rating'!A$8:B$11,2,FALSE) -> 3 | U7: =VLOOKUP(I7,'Maturity Rating'!A$14:B$17,2,FALSE) -> 3 | V7: =VLOOKUP(J7,'Maturity Rating'!A$20:B$23,2,FALSE) -> 3 | W7: =CONCATENATE(S7,T7,U7,V7) -> 3333
A8: 1.5 | E8: The information security policies and procedures shall be communicated to the employees and relevant external parties. | F8: Preventive | G8: Formally Documented | H8: 51 - 100% Implemented | I8: Automated | J8: Monitored & Reviewed | K8: =IF(W8="NANANANA",S8,IF(AND(OR(G8="Formally Documented",G8="Informally Documented"),H8="Not Implemented"),0.5*AVERAGE(S8:V8),AVERAGE(S8:V8))) -> 3 | L8: =IF(AND(D8="K",K8=1),'Maturity Rating'!$E$8,IF(K8="NA",K8,IF(D8="K",K8*'Maturity Rating'!$E$7,K8))) -> 3 | S8: =VLOOKUP(G8,'Maturity Rating'!A$2:B$5,2,FALSE) -> 3 | T8: =VLOOKUP(H8,'Maturity Rating'!A$8:B$11,2,FALSE) -> 3 | U8: =VLOOKUP(I8,'Maturity Rating'!A$14:B$17,2,FALSE) -> 3 | V8: =VLOOKUP(J8,'Maturity Rating'!A$20:B$23,2,FALSE) -> 3 | W8: =CONCATENATE(S8,T8,U8,V8) -> 3333
A9: 1.6 | E9: The version control of the document is maintained | F9: Preventive | G9: Formally Documented | H9: 51 - 100% Implemented | I9: Automated | J9: Monitored & Reviewed | K9: =IF(W9="NANANANA",S9,IF(AND(OR(G9="Formally Documented",G9="Informally Documented"),H9="Not Implemented"),0.5*AVERAGE(S9:V9),AVERAGE(S9:V9))) -> 3 | L9: =IF(AND(D9="K",K9=1),'Maturity Rating'!$E$8,IF(K9="NA",K9,IF(D9="K",K9*'Maturity Rating'!$E$7,K9))) -> 3 | S9: =VLOOKUP(G9,'Maturity Rating'!A$2:B$5,2,FALSE) -> 3 | T9: =VLOOKUP(H9,'Maturity Rating'!A$8:B$11,2,FALSE) -> 3 | U9: =VLOOKUP(I9,'Maturity Rating'!A$14:B$17,2,FALSE) -> 3 | V9: =VLOOKUP(J9,'Maturity Rating'!A$20:B$23,2,FALSE) -> 3 | W9: =CONCATENATE(S9,T9,U9,V9) -> 3333
A10: 1.7 | B10: Organization Structure | C10: Organization should ensure that the roles and responsibilities of all the employees are defined and the organization structure should be well maintained within the organization | D10: K | E10: Organization has a designated Chief Information Security Officer (CISO) responsible for Information security related decisions and operations. | F10: Preventive | G10: Formally Documented | H10: 51 - 100% Implemented | I10: Automated | J10: Monitored & Reviewed | K10: =IF(W10="NANANANA",S10,IF(AND(OR(G10="Formally Documented",G10="Informally Documented"),H10="Not Implemented"),0.5*AVERAGE(S10:V10),AVERAGE(S10:V10))) -> 3 | L10: =IF(AND(D10="K",K10=1),'Maturity Rating'!$E$8,IF(K10="NA",K10,IF(D10="K",K10*'Maturity Rating'!$E$7,K10))) -> 3.6 | M10: =IF(X10="NANANANANANANANA",K10,AVERAGE(L10:L16)) -> 2.2 | N10: =IF(M10<1.1,1,IF(M10="NA",M10,(MIN(5,M10/3*5)))) -> 3.6666667 | O10: =IF(N10="NA",N10,VLOOKUP(Q10,'Maturity Rating'!G4:H8,2,FALSE)) -> Defined | Q10: =IF(N10="NA",N10,ROUNDDOWN(N10,0)) -> 3 | S10: =VLOOKUP(G10,'Maturity Rating'!A$2:B$5,2,FALSE) -> 3 | T10: =VLOOKUP(H10,'Maturity Rating'!A$8:B$11,2,FALSE) -> 3 | U10: =VLOOKUP(I10,'Maturity Rating'!A$14:B$17,2,FALSE) -> 3 | V10: =VLOOKUP(J10,'Maturity Rating'!A$20:B$23,2,FALSE) -> 3 | W10: =CONCATENATE(S10,T10,U10,V10) -> 3333 | X10: =CONCATENATE(L10,L11,L12,L13,L14,L15,L16) -> 3.63310.831
A11: 1.8 | E11: Organization has an IS Steering Committee, the stakeholders are identified and periodicity for steering committee meeting is identified, documented and approved. | F11: Preventive | G11: Formally Documented | H11: 51 - 100% Implemented | I11: Automated | J11: Monitored & Reviewed | K11: =IF(W11="NANANANA",S11,IF(AND(OR(G11="Formally Documented",G11="Informally Documented"),H11="Not Implemented"),0.5*AVERAGE(S11:V11),AVERAGE(S11:V11))) -> 3 | L11: =IF(AND(D11="K",K11=1),'Maturity Rating'!$E$8,IF(K11="NA",K11,IF(D11="K",K11*'Maturity Rating'!$E$7,K11))) -> 3 | S11: =VLOOKUP(G11,'Maturity Rating'!A$2:B$5,2,FALSE) -> 3 | T11: =VLOOKUP(H11,'Maturity Rating'!A$8:B$11,2,FALSE) -> 3 | U11: =VLOOKUP(I11,'Maturity Rating'!A$14:B$17,2,FALSE) -> 3 | V11: =VLOOKUP(J11,'Maturity Rating'!A$20:B$23,2,FALSE) -> 3 | W11: =CONCATENATE(S11,T11,U11,V11) -> 3333
A12: 1.9 | E12: The policies, procedures, and processes to manage / monitor the organization’s regulatory, legal, risk, environmental, and operational requirements are understood and the IS Steering team or equivalent is informed of the cybersecurity risk. | F12: Preventive | G12: Formally Documented | H12: 51 - 100% Implemented | I12: Automated | J12: Monitored & Reviewed | K12: =IF(W12="NANANANA",S12,IF(AND(OR(G12="Formally Documented",G12="Informally Documented"),H12="Not Implemented"),0.5*AVERAGE(S12:V12),AVERAGE(S12:V12))) -> 3 | L12: =IF(AND(D12="K",K12=1),'Maturity Rating'!$E$8,IF(K12="NA",K12,IF(D12="K",K12*'Maturity Rating'!$E$7,K12))) -> 3 | S12: =VLOOKUP(G12,'Maturity Rating'!A$2:B$5,2,FALSE) -> 3 | T12: =VLOOKUP(H12,'Maturity Rating'!A$8:B$11,2,FALSE) -> 3 | U12: =VLOOKUP(I12,'Maturity Rating'!A$14:B$17,2,FALSE) -> 3 | V12: =VLOOKUP(J12,'Maturity Rating'!A$20:B$23,2,FALSE) -> 3 | W12: =CONCATENATE(S12,T12,U12,V12) -> 3333
A13: 1. 10 | E13: All information security responsibilities are defined and allocated to the identified personnel within the organization and among the external partners. | F13: Preventive | G13: Not Documented | H13: Not Applicable | I13: Not Applicable | J13: Not Applicable | K13: =IF(W13="NANANANA",S13,IF(AND(OR(G13="Formally Documented",G13="Informally Documented"),H13="Not Implemented"),0.5*AVERAGE(S13:V13),AVERAGE(S13:V13))) -> 1 | L13: =IF(AND(D13="K",K13=1),'Maturity Rating'!$E$8,IF(K13="NA",K13,IF(D13="K",K13*'Maturity Rating'!$E$7,K13))) -> 1 | S13: =VLOOKUP(G13,'Maturity Rating'!A$2:B$5,2,FALSE) -> 1 | T13: =VLOOKUP(H13,'Maturity Rating'!A$8:B$11,2,FALSE) -> NA | U13: =VLOOKUP(I13,'Maturity Rating'!A$14:B$17,2,FALSE) -> NA | V13: =VLOOKUP(J13,'Maturity Rating'!A$20:B$23,2,FALSE) -> NA | W13: =CONCATENATE(S13,T13,U13,V13) -> 1NANANA
A14: 1.11 | D14: K | E14: There is a RACI Matrix in place to hold the IS Organization Structure | F14: Preventive | G14: Not Documented | H14: Not Applicable | I14: Not Applicable | J14: Not Applicable | K14: =IF(W14="NANANANA",S14,IF(AND(OR(G14="Formally Documented",G14="Informally Documented"),H14="Not Implemented"),0.5*AVERAGE(S14:V14),AVERAGE(S14:V14))) -> 1 | L14: =IF(AND(D14="K",K14=1),'Maturity Rating'!$E$8,IF(K14="NA",K14,IF(D14="K",K14*'Maturity Rating'!$E$7,K14))) -> 0.8 | S14: =VLOOKUP(G14,'Maturity Rating'!A$2:B$5,2,FALSE) -> 1 | T14: =VLOOKUP(H14,'Maturity Rating'!A$8:B$11,2,FALSE) -> NA | U14: =VLOOKUP(I14,'Maturity Rating'!A$14:B$17,2,FALSE) -> NA | V14: =VLOOKUP(J14,'Maturity Rating'!A$20:B$23,2,FALSE) -> NA | W14: =CONCATENATE(S14,T14,U14,V14) -> 1NANANA
A15: 1.12 | E15: There is a clear segregation in functions of security group responsible for information security and the IT team which is responsible for the implementation and maintenance of IT Systems. | F15: Preventive | G15: Formally Documented | H15: 51 - 100% Implemented | I15: Automated | J15: Monitored & Reviewed | K15: =IF(W15="NANANANA",S15,IF(AND(OR(G15="Formally Documented",G15="Informally Documented"),H15="Not Implemented"),0.5*AVERAGE(S15:V15),AVERAGE(S15:V15))) -> 3 | L15: =IF(AND(D15="K",K15=1),'Maturity Rating'!$E$8,IF(K15="NA",K15,IF(D15="K",K15*'Maturity Rating'!$E$7,K15))) -> 3 | S15: =VLOOKUP(G15,'Maturity Rating'!A$2:B$5,2,FALSE) -> 3 | T15: =VLOOKUP(H15,'Maturity Rating'!A$8:B$11,2,FALSE) -> 3 | U15: =VLOOKUP(I15,'Maturity Rating'!A$14:B$17,2,FALSE) -> 3 | V15: =VLOOKUP(J15,'Maturity Rating'!A$20:B$23,2,FALSE) -> 3 | W15: =CONCATENATE(S15,T15,U15,V15) -> 3333
A16: 1.13 | E16: Every staff in the organization is made aware of the applicable laws, regulations, and guidelines pertaining to the usage, deployment and access to IT resources. | F16: Preventive | G16: Not Documented | H16: Not Applicable | I16: Not Applicable | J16: Not Applicable | K16: =IF(W16="NANANANA",S16,IF(AND(OR(G16="Formally Documented",G16="Informally Documented"),H16="Not Implemented"),0.5*AVERAGE(S16:V16),AVERAGE(S16:V16))) -> 1 | L16: =IF(AND(D16="K",K16=1),'Maturity Rating'!$E$8,IF(K16="NA",K16,IF(D16="K",K16*'Maturity Rating'!$E$7,K16))) -> 1 | S16: =VLOOKUP(G16,'Maturity Rating'!A$2:B$5,2,FALSE) -> 1 | T16: =VLOOKUP(H16,'Maturity Rating'!A$8:B$11,2,FALSE) -> NA | U16: =VLOOKUP(I16,'Maturity Rating'!A$14:B$17,2,FALSE) -> NA | V16: =VLOOKUP(J16,'Maturity Rating'!A$20:B$23,2,FALSE) -> NA | W16: =CONCATENATE(S16,T16,U16,V16) -> 1NANANA
A17: 1.14 | B17: Overall Governance of organization | C17: Providing a structure for aligning IT strategy with business strategy and provide management direction for information security | E17: The IS steering committee should ensure the alignment of IS strategy to the vision, mission, objectives and goal statements of the organization. | F17: Preventive | G17: Not Documented | H17: Not Applicable | I17: Not Applicable | J17: Not Applicable | K17: =IF(W17="NANANANA",S17,IF(AND(OR(G17="Formally Documented",G17="Informally Documented"),H17="Not Implemented"),0.5*AVERAGE(S17:V17),AVERAGE(S17:V17))) -> 1 | L17: =IF(AND(D17="K",K17=1),'Maturity Rating'!$E$8,IF(K17="NA",K17,IF(D17="K",K17*'Maturity Rating'!$E$7,K17))) -> 1 | M17: =IF(X17="NANANANANANANANANANA",K17,AVERAGE(L17:L20)) -> 1 | N17: =IF(M17<1.1,1,IF(M17="NA",M17,(MIN(5,M17/3*5)))) -> 1 | O17: =IF(N17="NA",N17,VLOOKUP(Q17,'Maturity Rating'!G4:H8,2,FALSE)) -> Initial | Q17: =IF(N17="NA",N17,ROUNDDOWN(N17,0)) -> 1 | S17: =VLOOKUP(G17,'Maturity Rating'!A$2:B$5,2,FALSE) -> 1 | T17: =VLOOKUP(H17,'Maturity Rating'!A$8:B$11,2,FALSE) -> NA | U17: =VLOOKUP(I17,'Maturity Rating'!A$14:B$17,2,FALSE) -> NA | V17: =VLOOKUP(J17,'Maturity Rating'!A$20:B$23,2,FALSE) -> NA | W17: =CONCATENATE(S17,T17,U17,V17) -> 1NANANA | X17: =CONCATENATE(L17,L18,L19,L20) -> 1111
A18: 1.15 | E18: Governance structure is identified and the personnel should be communicated their roles and responsibilities for effective governance of information security framework | F18: Preventive | G18: Not Documented | H18: Not Applicable | I18: Not Applicable | J18: Not Applicable | K18: =IF(W18="NANANANA",S18,IF(AND(OR(G18="Formally Documented",G18="Informally Documented"),H18="Not Implemented"),0.5*AVERAGE(S18:V18),AVERAGE(S18:V18))) -> 1 | L18: =IF(AND(D18="K",K18=1),'Maturity Rating'!$E$8,IF(K18="NA",K18,IF(D18="K",K18*'Maturity Rating'!$E$7,K18))) -> 1 | S18: =VLOOKUP(G18,'Maturity Rating'!A$2:B$5,2,FALSE) -> 1 | T18: =VLOOKUP(H18,'Maturity Rating'!A$8:B$11,2,FALSE) -> NA | U18: =VLOOKUP(I18,'Maturity Rating'!A$14:B$17,2,FALSE) -> NA | V18: =VLOOKUP(J18,'Maturity Rating'!A$20:B$23,2,FALSE) -> NA | W18: =CONCATENATE(S18,T18,U18,V18) -> 1NANANA
A19: 1.16 | E19: The annual budget for information security is approved by the top management. | F19: Preventive | G19: Not Documented | H19: Not Implemented | I19: Not Automated | J19: Not Monitored & Reviewed | K19: =IF(W19="NANANANA",S19,IF(AND(OR(G19="Formally Documented",G19="Informally Documented"),H19="Not Implemented"),0.5*AVERAGE(S19:V19),AVERAGE(S19:V19))) -> 1 | L19: =IF(AND(D19="K",K19=1),'Maturity Rating'!$E$8,IF(K19="NA",K19,IF(D19="K",K19*'Maturity Rating'!$E$7,K19))) -> 1 | S19: =VLOOKUP(G19,'Maturity Rating'!A$2:B$5,2,FALSE) -> 1 | T19: =VLOOKUP(H19,'Maturity Rating'!A$8:B$11,2,FALSE) -> 1 | U19: =VLOOKUP(I19,'Maturity Rating'!A$14:B$17,2,FALSE) -> 1 | V19: =VLOOKUP(J19,'Maturity Rating'!A$20:B$23,2,FALSE) -> 1 | W19: =CONCATENATE(S19,T19,U19,V19) -> 1111
A20: 1.17 | E20: The organization adopts security standards/guidelines as per the requirements of the industry sector, regulatory body or technology requirements | F20: Preventive | G20: Not Documented | H20: Not Implemented | I20: Not Automated | J20: Not Monitored & Reviewed | K20: =IF(W20="NANANANA",S20,IF(AND(OR(G20="Formally Documented",G20="Informally Documented"),H20="Not Implemented"),0.5*AVERAGE(S20:V20),AVERAGE(S20:V20))) -> 1 | L20: =IF(AND(D20="K",K20=1),'Maturity Rating'!$E$8,IF(K20="NA",K20,IF(D20="K",K20*'Maturity Rating'!$E$7,K20))) -> 1 | S20: =VLOOKUP(G20,'Maturity Rating'!A$2:B$5,2,FALSE) -> 1 | T20: =VLOOKUP(H20,'Maturity Rating'!A$8:B$11,2,FALSE) -> 1 | U20: =VLOOKUP(I20,'Maturity Rating'!A$14:B$17,2,FALSE) -> 1 | V20: =VLOOKUP(J20,'Maturity Rating'!A$20:B$23,2,FALSE) -> 1 | W20: =CONCATENATE(S20,T20,U20,V20) -> 1111

Sheet Access Management
C1: Average Domain Rating | E1: =IF(F1="NA","Not Applicable",VLOOKUP(T1,'Maturity Rating'!G4:H8,2,FALSE)) -> Partial | F1: =IF(U1="NANANANA","NA",AVERAGE(N4:N35)) -> 2.6837963 | T1: =ROUNDDOWN(F1,0) -> 2 | U1: =CONCATENATE(N4,N9,N18,N27) -> 3.355555555555563.259259259259263.120370370370371
A3: S. No. | B3: High Level Description | C3: Control Description | D3: Identified Key Controls (K) | E3: Control | F3: Preventive/ Detective/Corrective | G3: Documentation | H3: Implementation | I3: Automation | J3: Monitor & Review | K3: Control Rating | L3: Rating with Key controls weightage | M3: Average Rating | N3: Maturity Rating (1 - 5) | O3: Category | S3: Doc | T3: Impl | U3: Auto | V3: Review
A4: 2.1 | B4: Policy and procedures | C4: Access control policy should be established, documented and approved by authorised individuals. The document should be reviewed periodically and updated whenever significant changes occur. | D4: K | E4: Organization should have an Access Management policy/ procedure defined, approved by the management | F4: Preventive | G4: Informally Documented | H4: 0 - 50% Implemented | I4: Partially Automated | J4: Partially Monitored & Reviewed | K4: =IF(W4="NANANANA",S4,IF(AND(OR(G4="Formally Documented",G4="Informally Documented"),H4="Not Implemented"),0.5*AVERAGE(S4:V4),AVERAGE(S4:V4))) -> 2 | L4: =IF(AND(D4="K",K4=1),'Maturity Rating'!$E$8,IF(K4="NA",K4,IF(D4="K",K4*'Maturity Rating'!$E$7,K4))) -> 2.4 | M4: =IF(X4="NANANANA",K4,AVERAGE(L4:L8)) -> 2.0133333 | N4: =IF(M4<1.1,1,IF(M4="NA",M4,(MIN(5,M4/3*5)))) -> 3.3555556 | O4: =IF(N4="NA",N4,VLOOKUP(Q4,'Maturity Rating'!G4:H8,2,FALSE)) -> Defined | Q4: =IF(N4="NA",N4,ROUNDDOWN(N4,0)) -> 3 | S4: =VLOOKUP(G4,'Maturity Rating'!A$2:B$5,2,FALSE) -> 2 | T4: =VLOOKUP(H4,'Maturity Rating'!A$8:B$11,2,FALSE) -> 2 | U4: =VLOOKUP(I4,'Maturity Rating'!A$14:B$17,2,FALSE) -> 2 | V4: =VLOOKUP(J4,'Maturity Rating'!A$20:B$23,2,FALSE) -> 2 | W4: =CONCATENATE(S4,T4,U4,V4) -> 2222 | X4: =CONCATENATE(L4,L5,L6,L8) -> 2.421.666666666666671
A5: 2.2 | E5: Organization should have a password policy defined and approved by the management | F5: Preventive | G5: Informally Documented | H5: 0 - 50% Implemented | I5: Partially Automated | J5: Partially Monitored & Reviewed | K5: =IF(W5="NANANANA",S5,IF(AND(OR(G5="Formally Documented",G5="Informally Documented"),H5="Not Implemented"),0.5*AVERAGE(S5:V5),AVERAGE(S5:V5))) -> 2 | L5: =IF(AND(D5="K",K5=1),'Maturity Rating'!$E$8,IF(K5="NA",K5,IF(D5="K",K5*'Maturity Rating'!$E$7,K5))) -> 2 | S5: =VLOOKUP(G5,'Maturity Rating'!A$2:B$5,2,FALSE) -> 2 | T5: =VLOOKUP(H5,'Maturity Rating'!A$8:B$11,2,FALSE) -> 2 | U5: =VLOOKUP(I5,'Maturity Rating'!A$14:B$17,2,FALSE) -> 2 | V5: =VLOOKUP(J5,'Maturity Rating'!A$20:B$23,2,FALSE) -> 2 | W5: =CONCATENATE(S5,T5,U5,V5) -> 2222
A6: 2.3 | E6: The documents are reviewed, updated and approved as per the defined frequency in the policy/ procedure. | F6: Preventive | G6: Informally Documented | H6: 0 - 50% Implemented | I6: Not Automated | J6: Not Applicable | K6: =IF(W6="NANANANA",S6,IF(AND(OR(G6="Formally Documented",G6="Informally Documented"),H6="Not Implemented"),0.5*AVERAGE(S6:V6),AVERAGE(S6:V6))) -> 1.6666667 | L6: =IF(AND(D6="K",K6=1),'Maturity Rating'!$E$8,IF(K6="NA",K6,IF(D6="K",K6*'Maturity Rating'!$E$7,K6))) -> 1.6666667 | S6: =VLOOKUP(G6,'Maturity Rating'!A$2:B$5,2,FALSE) -> 2 | T6: =VLOOKUP(H6,'Maturity Rating'!A$8:B$11,2,FALSE) -> 2 | U6: =VLOOKUP(I6,'Maturity Rating'!A$14:B$17,2,FALSE) -> 1 | V6: =VLOOKUP(J6,'Maturity Rating'!A$20:B$23,2,FALSE) -> NA | W6: =CONCATENATE(S6,T6,U6,V6) -> 221NA
A7: 2.4 | E7: The version control of the documents should be maintained | F7: Preventive | G7: Formally Documented | H7: 51 - 100% Implemented | I7: Automated | J7: Monitored & Reviewed | K7: =IF(W7="NANANANA",S7,IF(AND(OR(G7="Formally Documented",G7="Informally Documented"),H7="Not Implemented"),0.5*AVERAGE(S7:V7),AVERAGE(S7:V7))) -> 3 | L7: =IF(AND(D7="K",K7=1),'Maturity Rating'!$E$8,IF(K7="NA",K7,IF(D7="K",K7*'Maturity Rating'!$E$7,K7))) -> 3 | S7: =VLOOKUP(G7,'Maturity Rating'!A$2:B$5,2,FALSE) -> 3 | T7: =VLOOKUP(H7,'Maturity Rating'!A$8:B$11,2,FALSE) -> 3 | U7: =VLOOKUP(I7,'Maturity Rating'!A$14:B$17,2,FALSE) -> 3 | V7: =VLOOKUP(J7,'Maturity Rating'!A$20:B$23,2,FALSE) -> 3 | W7: =CONCATENATE(S7,T7,U7,V7) -> 3333
A8: 2.5 | E8: There is process defined for the management of the Non-domain ID | F8: Preventive | G8: Not Documented | H8: Not Implemented | I8: Not Applicable | J8: Not Applicable | K8: =IF(W8="NANANANA",S8,IF(AND(OR(G8="Formally Documented",G8="Informally Documented"),H8="Not Implemented"),0.5*AVERAGE(S8:V8),AVERAGE(S8:V8))) -> 1 | L8: =IF(AND(D8="K",K8=1),'Maturity Rating'!$E$8,IF(K8="NA",K8,IF(D8="K",K8*'Maturity Rating'!$E$7,K8))) -> 1 | S8: =VLOOKUP(G8,'Maturity Rating'!A$2:B$5,2,FALSE) -> 1 | T8: =VLOOKUP(H8,'Maturity Rating'!A$8:B$11,2,FALSE) -> 1 | U8: =VLOOKUP(I8,'Maturity Rating'!A$14:B$17,2,FALSE) -> NA | V8: =VLOOKUP(J8,'Maturity Rating'!A$20:B$23,2,FALSE) -> NA | W8: =CONCATENATE(S8,T8,U8,V8) -> 11NANA
A9: 2.6 | B9: Access provisioning and deprovisioning | C9: There is a formal user access provisioning and de-provisioning process defined for granting and revoking access to all information systems and services.(for Employees and Third parties) | E9: Access to information systems and services should be granted only post authorised approvals | F9: Preventive | G9: Formally Documented | H9: 51 - 100% Implemented | I9: Automated | J9: Monitored & Reviewed | K9: =IF(W9="NANANANA",S9,IF(AND(OR(G9="Formally Documented",G9="Informally Documented"),H9="Not Implemented"),0.5*AVERAGE(S9:V9),AVERAGE(S9:V9))) -> 3 | L9: =IF(AND(D9="K",K9=1),'Maturity Rating'!$E$8,IF(K9="NA",K9,IF(D9="K",K9*'Maturity Rating'!$E$7,K9))) -> 3 | M9: =IF(X9="NANANANANANANANA",K9,AVERAGE(L9:L17)) -> 1.9555556 | N9: =IF(M9<1.1,1,IF(M9="NA",M9,(MIN(5,M9/3*5)))) -> 3.2592593 | O9: =IF(N9="NA",N9,VLOOKUP(Q9,'Maturity Rating'!G4:H8,2,FALSE)) -> Defined | Q9: =IF(N9="NA",N9,ROUNDDOWN(N9,0)) -> 3 | S9: =VLOOKUP(G9,'Maturity Rating'!A$2:B$5,2,FALSE) -> 3 | T9: =VLOOKUP(H9,'Maturity Rating'!A$8:B$11,2,FALSE) -> 3 | U9: =VLOOKUP(I9,'Maturity Rating'!A$14:B$17,2,FALSE) -> 3 | V9: =VLOOKUP(J9,'Maturity Rating'!A$20:B$23,2,FALSE) -> 3 | W9: =CONCATENATE(S9,T9,U9,V9) -> 3333 | X9: =CONCATENATE(L9,L10,L11,L12,L13,L14,L15,L16,L17) -> 311.533.612.511
A10: 2.7 | E10: Access rights are granted based on the principle of least privilege | F10: Preventive | G10: Not Documented | H10: Not Implemented | I10: Not Automated | J10: Not Monitored & Reviewed | K10: =IF(W10="NANANANA",S10,IF(AND(OR(G10="Formally Documented",G10="Informally Documented"),H10="Not Implemented"),0.5*AVERAGE(S10:V10),AVERAGE(S10:V10))) -> 1 | L10: =IF(AND(D10="K",K10=1),'Maturity Rating'!$E$8,IF(K10="NA",K10,IF(D10="K",K10*'Maturity Rating'!$E$7,K10))) -> 1 | S10: =VLOOKUP(G10,'Maturity Rating'!A$2:B$5,2,FALSE) -> 1 | T10: =VLOOKUP(H10,'Maturity Rating'!A$8:B$11,2,FALSE) -> 1 | U10: =VLOOKUP(I10,'Maturity Rating'!A$14:B$17,2,FALSE) -> 1 | V10: =VLOOKUP(J10,'Maturity Rating'!A$20:B$23,2,FALSE) -> 1 | W10: =CONCATENATE(S10,T10,U10,V10) -> 1111
A11: 2.8 | E11: User IDs are uniquely created to establish accountability within the organization and generic IDs should be used subject to management approval | F11: Detective | G11: Informally Documented | H11: 0 - 50% Implemented | I11: Not Automated | J11: Not Monitored & Reviewed | K11: =IF(W11="NANANANA",S11,IF(AND(OR(G11="Formally Documented",G11="Informally Documented"),H11="Not Implemented"),0.5*AVERAGE(S11:V11),AVERAGE(S11:V11))) -> 1.5 | L11: =IF(AND(D11="K",K11=1),'Maturity Rating'!$E$8,IF(K11="NA",K11,IF(D11="K",K11*'Maturity Rating'!$E$7,K11))) -> 1.5 | S11: =VLOOKUP(G11,'Maturity Rating'!A$2:B$5,2,FALSE) -> 2 | T11: =VLOOKUP(H11,'Maturity Rating'!A$8:B$11,2,FALSE) -> 2 | U11: =VLOOKUP(I11,'Maturity Rating'!A$14:B$17,2,FALSE) -> 1 | V11: =VLOOKUP(J11,'Maturity Rating'!A$20:B$23,2,FALSE) -> 1 | W11: =CONCATENATE(S11,T11,U11,V11) -> 2211
A12: 2.9 | E12: Central record is maintained of all access rights granted to users. | F12: Detective | G12: Formally Documented | H12: 51 - 100% Implemented | I12: Automated | J12: Monitored & Reviewed | K12: =IF(W12="NANANANA",S12,IF(AND(OR(G12="Formally Documented",G12="Informally Documented"),H12="Not Implemented"),0.5*AVERAGE(S12:V12),AVERAGE(S12:V12))) -> 3 | L12: =IF(AND(D12="K",K12=1),'Maturity Rating'!$E$8,IF(K12="NA",K12,IF(D12="K",K12*'Maturity Rating'!$E$7,K12))) -> 3 | S12: =VLOOKUP(G12,'Maturity Rating'!A$2:B$5,2,FALSE) -> 3 | T12: =VLOOKUP(H12,'Maturity Rating'!A$8:B$11,2,FALSE) -> 3 | U12: =VLOOKUP(I12,'Maturity Rating'!A$14:B$17,2,FALSE) -> 3 | V12: =VLOOKUP(J12,'Maturity Rating'!A$20:B$23,2,FALSE) -> 3 | W12: =CONCATENATE(S12,T12,U12,V12) -> 3333
A13: 2. 10 | D13: K | E13: User access rights are reviewed by the authorised personnel at regular intervals defined in policy/ procedures. | F13: Preventive | G13: Formally Documented | H13: 51 - 100% Implemented | I13: Automated | J13: Monitored & Reviewed | K13: =IF(W13="NANANANA",S13,IF(AND(OR(G13="Formally Documented",G13="Informally Documented"),H13="Not Implemented"),0.5*AVERAGE(S13:V13),AVERAGE(S13:V13))) -> 3 | L13: =IF(AND(D13="K",K13=1),'Maturity Rating'!$E$8,IF(K13="NA",K13,IF(D13="K",K13*'Maturity Rating'!$E$7,K13))) -> 3.6 | S13: =VLOOKUP(G13,'Maturity Rating'!A$2:B$5,2,FALSE) -> 3 | T13: =VLOOKUP(H13,'Maturity Rating'!A$8:B$11,2,FALSE) -> 3 | U13: =VLOOKUP(I13,'Maturity Rating'!A$14:B$17,2,FALSE) -> 3 | V13: =VLOOKUP(J13,'Maturity Rating'!A$20:B$23,2,FALSE) -> 3 | W13: =CONCATENATE(S13,T13,U13,V13) -> 3333
A14: 2.11 | E14: Access to information systems and services should be revoked post termination of the employee within the defined period. | F14: Preventive | G14: Not Documented | H14: Not Implemented | I14: Not Automated | J14: Not Monitored & Reviewed | K14: =IF(W14="NANANANA",S14,IF(AND(OR(G14="Formally Documented",G14="Informally Documented"),H14="Not Implemented"),0.5*AVERAGE(S14:V14),AVERAGE(S14:V14))) -> 1 | L14: =IF(AND(D14="K",K14=1),'Maturity Rating'!$E$8,IF(K14="NA",K14,IF(D14="K",K14*'Maturity Rating'!$E$7,K14))) -> 1 | S14: =VLOOKUP(G14,'Maturity Rating'!A$2:B$5,2,FALSE) -> 1 | T14: =VLOOKUP(H14,'Maturity Rating'!A$8:B$11,2,FALSE) -> 1 | U14: =VLOOKUP(I14,'Maturity Rating'!A$14:B$17,2,FALSE) -> 1 | V14: =VLOOKUP(J14,'Maturity Rating'!A$20:B$23,2,FALSE) -> 1 | W14: =CONCATENATE(S14,T14,U14,V14) -> 1111
A15: 2.12 | E15: "Restricted access and authorised use only" warnings are displayed upon access to all systems | F15: Preventive | G15: Formally Documented | H15: 51 - 100% Implemented | I15: Automated | J15: Not Monitored & Reviewed | K15: =IF(W15="NANANANA",S15,IF(AND(OR(G15="Formally Documented",G15="Informally Documented"),H15="Not Implemented"),0.5*AVERAGE(S15:V15),AVERAGE(S15:V15))) -> 2.5 | L15: =IF(AND(D15="K",K15=1),'Maturity Rating'!$E$8,IF(K15="NA",K15,IF(D15="K",K15*'Maturity Rating'!$E$7,K15))) -> 2.5 | S15: =VLOOKUP(G15,'Maturity Rating'!A$2:B$5,2,FALSE) -> 3 | T15: =VLOOKUP(H15,'Maturity Rating'!A$8:B$11,2,FALSE) -> 3 | U15: =VLOOKUP(I15,'Maturity Rating'!A$14:B$17,2,FALSE) -> 3 | V15: =VLOOKUP(J15,'Maturity Rating'!A$20:B$23,2,FALSE) -> 1 | W15: =CONCATENATE(S15,T15,U15,V15) -> 3331
A16: 2.13 | E16: Application specific user review are performed as per the defined frequency in the policy/ procedure. Also inactive user are disabled. | F16: Preventive | G16: Not Documented | H16: Not Implemented | I16: Not Automated | J16: Not Monitored & Reviewed | K16: =IF(W16="NANANANA",S16,IF(AND(OR(G16="Formally Documented",G16="Informally Documented"),H16="Not Implemented"),0.5*AVERAGE(S16:V16),AVERAGE(S16:V16))) -> 1 | L16: =IF(AND(D16="K",K16=1),'Maturity Rating'!$E$8,IF(K16="NA",K16,IF(D16="K",K16*'Maturity Rating'!$E$7,K16))) -> 1 | S16: =VLOOKUP(G16,'Maturity Rating'!A$2:B$5,2,FALSE) -> 1 | T16: =VLOOKUP(H16,'Maturity Rating'!A$8:B$11,2,FALSE) -> 1 | U16: =VLOOKUP(I16,'Maturity Rating'!A$14:B$17,2,FALSE) -> 1 | V16: =VLOOKUP(J16,'Maturity Rating'!A$20:B$23,2,FALSE) -> 1 | W16: =CONCATENATE(S16,T16,U16,V16) -> 1111
A17: 2.14 | E17: Enable accounts used by vendors for remote maintenance only during the time needed. | F17: Preventive | G17: Not Documented | H17: Not Implemented | I17: Not Automated | J17: Not Monitored & Reviewed | K17: =IF(W17="NANANANA",S17,IF(AND(OR(G17="Formally Documented",G17="Informally Documented"),H17="Not Implemented"),0.5*AVERAGE(S17:V17),AVERAGE(S17:V17))) -> 1 | L17: =IF(AND(D17="K",K17=1),'Maturity Rating'!$E$8,IF(K17="NA",K17,IF(D17="K",K17*'Maturity Rating'!$E$7,K17))) -> 1 | S17: =VLOOKUP(G17,'Maturity Rating'!A$2:B$5,2,FALSE) -> 1 | T17: =VLOOKUP(H17,'Maturity Rating'!A$8:B$11,2,FALSE) -> 1 | U17: =VLOOKUP(I17,'Maturity Rating'!A$14:B$17,2,FALSE) -> 1 | V17: =VLOOKUP(J17,'Maturity Rating'!A$20:B$23,2,FALSE) -> 1 | W17: =CONCATENATE(S17,T17,U17,V17) -> 1111
A18: 2.15 | B18: Password Management | C18: Secure password management processes should be implemented consistently within the organization | E18: Passwords for the end users and administrators must be configured based on the password policy defined for the organization. | F18: Preventive | G18: Not Documented | H18: Not Implemented | I18: Not Applicable | J18: Not Applicable | K18: =IF(W18="NANANANA",S18,IF(AND(OR(G18="Formally Documented",G18="Informally Documented"),H18="Not Implemented"),0.5*AVERAGE(S18:V18),AVERAGE(S18:V18))) -> 1 | L18: =IF(AND(D18="K",K18=1),'Maturity Rating'!$E$8,IF(K18="NA",K18,IF(D18="K",K18*'Maturity Rating'!$E$7,K18))) -> 1 | M18: =IF(X18="NANANANANANANANANANA",K18,AVERAGE(L18:L26)) -> 1.8722222 | N18: =IF(M18<1.1,1,IF(M18="NA",M18,(MIN(5,M18/3*5)))) -> 3.1203704 | O18: =IF(N18="NA",N18,VLOOKUP(Q18,'Maturity Rating'!G4:H8,2,FALSE)) -> Defined | Q18: =IF(N18="NA",N18,ROUNDDOWN(N18,0)) -> 3 | S18: =VLOOKUP(G18,'Maturity Rating'!A$2:B$5,2,FALSE) -> 1 | T18: =VLOOKUP(H18,'Maturity Rating'!A$8:B$11,2,FALSE) -> 1 | U18: =VLOOKUP(I18,'Maturity Rating'!A$14:B$17,2,FALSE) -> NA | V18: =VLOOKUP(J18,'Maturity Rating'!A$20:B$23,2,FALSE) -> NA | W18: =CONCATENATE(S18,T18,U18,V18) -> 11NANA | X18: =CONCATENATE(L18,L19,L20,L21,L22,L23,L24,L26) -> 12.52.753.61131
A19: 2.16 | E19: All default manufacturers passwords and/or end user passwords are changed upon first login. Also the user should be asked to reset its password upon first login | F19: Preventive | G19: Formally Documented | H19: 51 - 100% Implemented | I19: Automated | J19: Not Monitored & Reviewed | K19: =IF(W19="NANANANA",S19,IF(AND(OR(G19="Formally Documented",G19="Informally Documented"),H19="Not Implemented"),0.5*AVERAGE(S19:V19),AVERAGE(S19:V19))) -> 2.5 | L19: =IF(AND(D19="K",K19=1),'Maturity Rating'!$E$8,IF(K19="NA",K19,IF(D19="K",K19*'Maturity Rating'!$E$7,K19))) -> 2.5 | S19: =VLOOKUP(G19,'Maturity Rating'!A$2:B$5,2,FALSE) -> 3 | T19: =VLOOKUP(H19,'Maturity Rating'!A$8:B$11,2,FALSE) -> 3 | U19: =VLOOKUP(I19,'Maturity Rating'!A$14:B$17,2,FALSE) -> 3 | V19: =VLOOKUP(J19,'Maturity Rating'!A$20:B$23,2,FALSE) -> 1 | W19: =CONCATENATE(S19,T19,U19,V19) -> 3331
A20: 2.17 | E20: Password should be stored securely and should not be shared with anyone. | F20: Preventive | G20: Formally Documented | H20: 51 - 100% Implemented | I20: Automated | J20: Partially Monitored & Reviewed | K20: =IF(W20="NANANANA",S20,IF(AND(OR(G20="Formally Documented",G20="Informally Documented"),H20="Not Implemented"),0.5*AVERAGE(S20:V20),AVERAGE(S20:V20))) -> 2.75 | L20: =IF(AND(D20="K",K20=1),'Maturity Rating'!$E$8,IF(K20="NA",K20,IF(D20="K",K20*'Maturity Rating'!$E$7,K20))) -> 2.75 | S20: =VLOOKUP(G20,'Maturity Rating'!A$2:B$5,2,FALSE) -> 3 | T20: =VLOOKUP(H20,'Maturity Rating'!A$8:B$11,2,FALSE) -> 3 | U20: =VLOOKUP(I20,'Maturity Rating'!A$14:B$17,2,FALSE) -> 3 | V20: =VLOOKUP(J20,'Maturity Rating'!A$20:B$23,2,FALSE) -> 2 | W20: =CONCATENATE(S20,T20,U20,V20) -> 3332
A21: 2.18 | D21: K | E21: Password should be alpha numeric, special character, minimum 8 characters and should not include dictionary words. | F21: Preventive | G21: Formally Documented | H21: 51 - 100% Implemented | I21: Automated | J21: Monitored & Reviewed | K21: =IF(W21="NANANANA",S21,IF(AND(OR(G21="Formally Documented",G21="Informally Documented"),H21="Not Implemented"),0.5*AVERAGE(S21:V21),AVERAGE(S21:V21))) -> 3 | L21: =IF(AND(D21="K",K21=1),'Maturity Rating'!$E$8,IF(K21="NA",K21,IF(D21="K",K21*'Maturity Rating'!$E$7,K21))) -> 3.6 | S21: =VLOOKUP(G21,'Maturity Rating'!A$2:B$5,2,FALSE) -> 3 | T21: =VLOOKUP(H21,'Maturity Rating'!A$8:B$11,2,FALSE) -> 3 | U21: =VLOOKUP(I21,'Maturity Rating'!A$14:B$17,2,FALSE) -> 3 | V21: =VLOOKUP(J21,'Maturity Rating'!A$20:B$23,2,FALSE) -> 3 | W21: =CONCATENATE(S21,T21,U21,V21) -> 3333
A22: 2.19 | E22: There is an enforced limit of invalid / failed logon attempts as per the defined password management policy of the organization | F22: Preventive | G22: Not Documented | H22: Not Implemented | I22: Not Automated | J22: Not Monitored & Reviewed | K22: =IF(W22="NANANANA",S22,IF(AND(OR(G22="Formally Documented",G22="Informally Documented"),H22="Not Implemented"),0.5*AVERAGE(S22:V22),AVERAGE(S22:V22))) -> 1 | L22: =IF(AND(D22="K",K22=1),'Maturity Rating'!$E$8,IF(K22="NA",K22,IF(D22="K",K22*'Maturity Rating'!$E$7,K22))) -> 1 | S22: =VLOOKUP(G22,'Maturity Rating'!A$2:B$5,2,FALSE) -> 1 | T22: =VLOOKUP(H22,'Maturity Rating'!A$8:B$11,2,FALSE) -> 1 | U22: =VLOOKUP(I22,'Maturity Rating'!A$14:B$17,2,FALSE) -> 1 | V22: =VLOOKUP(J22,'Maturity Rating'!A$20:B$23,2,FALSE) -> 1 | W22: =CONCATENATE(S22,T22,U22,V22) -> 1111
A23: 2. 20 | E23: The session should be automatically locked as per the duration defined by the organization. | F23: Preventive | G23: Not Documented | H23: Not Implemented | I23: Not Automated | J23: Not Monitored & Reviewed | K23: =IF(W23="NANANANA",S23,IF(AND(OR(G23="Formally Documented",G23="Informally Documented"),H23="Not Implemented"),0.5*AVERAGE(S23:V23),AVERAGE(S23:V23))) -> 1 | L23: =IF(AND(D23="K",K23=1),'Maturity Rating'!$E$8,IF(K23="NA",K23,IF(D23="K",K23*'Maturity Rating'!$E$7,K23))) -> 1 | S23: =VLOOKUP(G23,'Maturity Rating'!A$2:B$5,2,FALSE) -> 1 | T23: =VLOOKUP(H23,'Maturity Rating'!A$8:B$11,2,FALSE) -> 1 | U23: =VLOOKUP(I23,'Maturity Rating'!A$14:B$17,2,FALSE) -> 1 | V23: =VLOOKUP(J23,'Maturity Rating'!A$20:B$23,2,FALSE) -> 1 | W23: =CONCATENATE(S23,T23,U23,V23) -> 1111
A24: 2.23 | E24: Passwords should be changed at periodic intervals as per the password policy of the organization. | F24: Preventive | G24: Formally Documented | H24: 51 - 100% Implemented | I24: Automated | J24: Monitored & Reviewed | K24: =IF(W24="NANANANA",S24,IF(AND(OR(G24="Formally Documented",G24="Informally Documented"),H24="Not Implemented"),0.5*AVERAGE(S24:V24),AVERAGE(S24:V24))) -> 3 | L24: =IF(AND(D24="K",K24=1),'Maturity Rating'!$E$8,IF(K24="NA",K24,IF(D24="K",K24*'Maturity Rating'!$E$7,K24))) -> 3 | S24: =VLOOKUP(G24,'Maturity Rating'!A$2:B$5,2,FALSE) -> 3 | T24: =VLOOKUP(H24,'Maturity Rating'!A$8:B$11,2,FALSE) -> 3 | U24: =VLOOKUP(I24,'Maturity Rating'!A$14:B$17,2,FALSE) -> 3 | V24: =VLOOKUP(J24,'Maturity Rating'!A$20:B$23,2,FALSE) -> 3 | W24: =CONCATENATE(S24,T24,U24,V24) -> 3333
A25: 2.24 | E25: Service accounts with password never expiry are non-interactive. | F25: Preventive | G25: Not Documented | H25: Not Implemented | I25: Not Applicable | J25: Not Monitored & Reviewed | K25: =IF(W25="NANANANA",S25,IF(AND(OR(G25="Formally Documented",G25="Informally Documented"),H25="Not Implemented"),0.5*AVERAGE(S25:V25),AVERAGE(S25:V25))) -> 1 | L25: =IF(AND(D25="K",K25=1),'Maturity Rating'!$E$8,IF(K25="NA",K25,IF(D25="K",K25*'Maturity Rating'!$E$7,K25))) -> 1 | S25: =VLOOKUP(G25,'Maturity Rating'!A$2:B$5,2,FALSE) -> 1 | T25: =VLOOKUP(H25,'Maturity Rating'!A$8:B$11,2,FALSE) -> 1 | U25: =VLOOKUP(I25,'Maturity Rating'!A$14:B$17,2,FALSE) -> NA | V25: =VLOOKUP(J25,'Maturity Rating'!A$20:B$23,2,FALSE) -> 1 | W25: =CONCATENATE(S25,T25,U25,V25) -> 11NA1
A26: 2.25 | E26: Secret authentication information such as tokens, OTPs are used to login on critical applications and systems. | F26: Preventive | G26: Not Documented | H26: Not Implemented | I26: Not Automated | J26: Not Monitored & Reviewed | K26: =IF(W26="NANANANA",S26,IF(AND(OR(G26="Formally Documented",G26="Informally Documented"),H26="Not Implemented"),0.5*AVERAGE(S26:V26),AVERAGE(S26:V26))) -> 1 | L26: =IF(AND(D26="K",K26=1),'Maturity Rating'!$E$8,IF(K26="NA",K26,IF(D26="K",K26*'Maturity Rating'!$E$7,K26))) -> 1 | S26: =VLOOKUP(G26,'Maturity Rating'!A$2:B$5,2,FALSE) -> 1 | T26: =VLOOKUP(H26,'Maturity Rating'!A$8:B$11,2,FALSE) -> 1 | U26: =VLOOKUP(I26,'Maturity Rating'!A$14:B$17,2,FALSE) -> 1 | V26: =VLOOKUP(J26,'Maturity Rating'!A$20:B$23,2,FALSE) -> 1 | W26: =CONCATENATE(S26,T26,U26,V26) -> 1111
A27: 2.26 | B27: Privileged Identity Management | C27: Privileged access to information and services should be given on a need-to-know basis and should be managed securely. Applicability to Production/Dev/UAT and types of system(Servers, DB, Appliances, Network) | D27: K | E27: Access privileges must be granted based on the approvals by an authorised personnel. | F27: Preventive | G27: Not Documented | H27: Not Implemented | I27: Not Applicable | J27: Not Monitored & Reviewed | K27: =IF(W27="NANANANA",S27,IF(AND(OR(G27="Formally Documented",G27="Informally Documented"),H27="Not Implemented"),0.5*AVERAGE(S27:V27),AVERAGE(S27:V27))) -> 1 | L27: =IF(AND(D27="K",K27=1),'Maturity Rating'!$E$8,IF(K27="NA",K27,IF(D27="K",K27*'Maturity Rating'!$E$7,K27))) -> 0.8 | M27: =IF(X27="NANANANANANANA",K27,AVERAGE(L27:L35)) -> 0.975 | N27: =IF(M27<1.1,1,IF(M27="NA",M27,(MIN(5,M27/3*5)))) -> 1 | O27: =IF(N27="NA",N27,VLOOKUP(Q27,'Maturity Rating'!G4:H8,2,FALSE)) -> Initial | Q27: =IF(N27="NA",N27,ROUNDDOWN(N27,0)) -> 1 | S27: =VLOOKUP(G27,'Maturity Rating'!A$2:B$5,2,FALSE) -> 1 | T27: =VLOOKUP(H27,'Maturity Rating'!A$8:B$11,2,FALSE) -> 1 | U27: =VLOOKUP(I27,'Maturity Rating'!A$14:B$17,2,FALSE) -> NA | V27: =VLOOKUP(J27,'Maturity Rating'!A$20:B$23,2,FALSE) -> 1 | W27: =CONCATENATE(S27,T27,U27,V27) -> 11NA1 | X27: =CONCATENATE(L27,L28,L29,L30,L31,L32,L33,L34,L35) -> 0.811111NA11
A28: 2.27 | E28: Administrative activities are logged and the audit trails must be stored. | F28: Detective | G28: Not Documented | H28: Not Implemented | I28: Not Automated | J28: Not Monitored & Reviewed | K28: =IF(W28="NANANANA",S28,IF(AND(OR(G28="Formally Documented",G28="Informally Documented"),H28="Not Implemented"),0.5*AVERAGE(S28:V28),AVERAGE(S28:V28))) -> 1 | L28: =IF(AND(D28="K",K28=1),'Maturity Rating'!$E$8,IF(K28="NA",K28,IF(D28="K",K28*'Maturity Rating'!$E$7,K28))) -> 1 | S28: =VLOOKUP(G28,'Maturity Rating'!A$2:B$5,2,FALSE) -> 1 | T28: =VLOOKUP(H28,'Maturity Rating'!A$8:B$11,2,FALSE) -> 1 | U28: =VLOOKUP(I28,'Maturity Rating'!A$14:B$17,2,FALSE) -> 1 | V28: =VLOOKUP(J28,'Maturity Rating'!A$20:B$23,2,FALSE) -> 1 | W28: =CONCATENATE(S28,T28,U28,V28) -> 1111
A29: 2.28 | E29: Administrative IDs must be reviewed on a periodic basis by authorised personnel | F29: Detective | G29: Not Documented | H29: Not Implemented | I29: Not Automated | J29: Not Monitored & Reviewed | K29: =IF(W29="NANANANA",S29,IF(AND(OR(G29="Formally Documented",G29="Informally Documented"),H29="Not Implemented"),0.5*AVERAGE(S29:V29),AVERAGE(S29:V29))) -> 1 | L29: =IF(AND(D29="K",K29=1),'Maturity Rating'!$E$8,IF(K29="NA",K29,IF(D29="K",K29*'Maturity Rating'!$E$7,K29))) -> 1 | S29: =VLOOKUP(G29,'Maturity Rating'!A$2:B$5,2,FALSE) -> 1 | T29: =VLOOKUP(H29,'Maturity Rating'!A$8:B$11,2,FALSE) -> 1 | U29: =VLOOKUP(I29,'Maturity Rating'!A$14:B$17,2,FALSE) -> 1 | V29: =VLOOKUP(J29,'Maturity Rating'!A$20:B$23,2,FALSE) -> 1 | W29: =CONCATENATE(S29,T29,U29,V29) -> 1111
A30: 2.29 | E30: The privileged access rights must be revoked after the expiration of the validity period as mentioned in the user access management procedure | F30: Preventive | G30: Not Documented | H30: Not Implemented | I30: Not Automated | J30: Not Monitored & Reviewed | K30: =IF(W30="NANANANA",S30,IF(AND(OR(G30="Formally Documented",G30="Informally Documented"),H30="Not Implemented"),0.5*AVERAGE(S30:V30),AVERAGE(S30:V30))) -> 1 | L30: =IF(AND(D30="K",K30=1),'Maturity Rating'!$E$8,IF(K30="NA",K30,IF(D30="K",K30*'Maturity Rating'!$E$7,K30))) -> 1 | S30: =VLOOKUP(G30,'Maturity Rating'!A$2:B$5,2,FALSE) -> 1 | T30: =VLOOKUP(H30,'Maturity Rating'!A$8:B$11,2,FALSE) -> 1 | U30: =VLOOKUP(I30,'Maturity Rating'!A$14:B$17,2,FALSE) -> 1 | V30: =VLOOKUP(J30,'Maturity Rating'!A$20:B$23,2,FALSE) -> 1 | W30: =CONCATENATE(S30,T30,U30,V30) -> 1111
A31: 2. 30 | E31: There is a privilege identity management tool implemented for monitoring the privilege activity | F31: Detective | G31: Not Documented | H31: Not Implemented | I31: Not Automated | J31: Not Monitored & Reviewed | K31: =IF(W31="NANANANA",S31,IF(AND(OR(G31="Formally Documented",G31="Informally Documented"),H31="Not Implemented"),0.5*AVERAGE(S31:V31),AVERAGE(S31:V31))) -> 1 | L31: =IF(AND(D31="K",K31=1),'Maturity Rating'!$E$8,IF(K31="NA",K31,IF(D31="K",K31*'Maturity Rating'!$E$7,K31))) -> 1 | S31: =VLOOKUP(G31,'Maturity Rating'!A$2:B$5,2,FALSE) -> 1 | T31: =VLOOKUP(H31,'Maturity Rating'!A$8:B$11,2,FALSE) -> 1 | U31: =VLOOKUP(I31,'Maturity Rating'!A$14:B$17,2,FALSE) -> 1 | V31: =VLOOKUP(J31,'Maturity Rating'!A$20:B$23,2,FALSE) -> 1 | W31: =CONCATENATE(S31,T31,U31,V31) -> 1111
A32: 2.31 | E32: Privileged accounts are not shared among multiple users. | F32: Preventive | G32: Not Documented | H32: Not Implemented | I32: Not Automated | J32: Not Monitored & Reviewed | K32: =IF(W32="NANANANA",S32,IF(AND(OR(G32="Formally Documented",G32="Informally Documented"),H32="Not Implemented"),0.5*AVERAGE(S32:V32),AVERAGE(S32:V32))) -> 1 | L32: =IF(AND(D32="K",K32=1),'Maturity Rating'!$E$8,IF(K32="NA",K32,IF(D32="K",K32*'Maturity Rating'!$E$7,K32))) -> 1 | S32: =VLOOKUP(G32,'Maturity Rating'!A$2:B$5,2,FALSE) -> 1 | T32: =VLOOKUP(H32,'Maturity Rating'!A$8:B$11,2,FALSE) -> 1 | U32: =VLOOKUP(I32,'Maturity Rating'!A$14:B$17,2,FALSE) -> 1 | V32: =VLOOKUP(J32,'Maturity Rating'!A$20:B$23,2,FALSE) -> 1 | W32: =CONCATENATE(S32,T32,U32,V32) -> 1111
A33: 2.32 | E33: Multifactor authentication should be implemented for PIM | F33: Preventive | G33: Not Applicable | H33: Not Applicable | I33: Not Applicable | J33: Not Applicable | K33: =IF(W33="NANANANA",S33,IF(AND(OR(G33="Formally Documented",G33="Informally Documented"),H33="Not Implemented"),0.5*AVERAGE(S33:V33),AVERAGE(S33:V33))) -> NA | L33: =IF(AND(D33="K",K33=1),'Maturity Rating'!$E$8,IF(K33="NA",K33,IF(D33="K",K33*'Maturity Rating'!$E$7,K33))) -> NA | S33: =VLOOKUP(G33,'Maturity Rating'!A$2:B$5,2,FALSE) -> NA | T33: =VLOOKUP(H33,'Maturity Rating'!A$8:B$11,2,FALSE) -> NA | U33: =VLOOKUP(I33,'Maturity Rating'!A$14:B$17,2,FALSE) -> NA | V33: =VLOOKUP(J33,'Maturity Rating'!A$20:B$23,2,FALSE) -> NA | W33: =CONCATENATE(S33,T33,U33,V33) -> NANANANA
A34: 2.33 | E34: There should be a defined process in place to detect any PIM bypass | F34: Detective | G34: Not Documented | H34: Not Implemented | I34: Not Automated | J34: Not Monitored & Reviewed | K34: =IF(W34="NANANANA",S34,IF(AND(OR(G34="Formally Documented",G34="Informally Documented"),H34="Not Implemented"),0.5*AVERAGE(S34:V34),AVERAGE(S34:V34))) -> 1 | L34: =IF(AND(D34="K",K34=1),'Maturity Rating'!$E$8,IF(K34="NA",K34,IF(D34="K",K34*'Maturity Rating'!$E$7,K34))) -> 1 | S34: =VLOOKUP(G34,'Maturity Rating'!A$2:B$5,2,FALSE) -> 1 | T34: =VLOOKUP(H34,'Maturity Rating'!A$8:B$11,2,FALSE) -> 1 | U34: =VLOOKUP(I34,'Maturity Rating'!A$14:B$17,2,FALSE) -> 1 | V34: =VLOOKUP(J34,'Maturity Rating'!A$20:B$23,2,FALSE) -> 1 | W34: =CONCATENATE(S34,T34,U34,V34) -> 1111
A35: 2.34 | E35: Administrative credentials are stored securely either with an authorised personnel or in a safe custody. | F35: Preventive | G35: Not Documented | H35: Not Implemented | I35: Not Automated | J35: Not Monitored & Reviewed | K35: =IF(W35="NANANANA",S35,IF(AND(OR(G35="Formally Documented",G35="Informally Documented"),H35="Not Implemented"),0.5*AVERAGE(S35:V35),AVERAGE(S35:V35))) -> 1 | L35: =IF(AND(D35="K",K35=1),'Maturity Rating'!$E$8,IF(K35="NA",K35,IF(D35="K",K35*'Maturity Rating'!$E$7,K35))) -> 1 | S35: =VLOOKUP(G35,'Maturity Rating'!A$2:B$5,2,FALSE) -> 1 | T35: =VLOOKUP(H35,'Maturity Rating'!A$8:B$11,2,FALSE) -> 1 | U35: =VLOOKUP(I35,'Maturity Rating'!A$14:B$17,2,FALSE) -> 1 | V35: =VLOOKUP(J35,'Maturity Rating'!A$20:B$23,2,FALSE) -> 1 | W35: =CONCATENATE(S35,T35,U35,V35) -> 1111

Sheet Asset Management
C1: Average Domain Rating | E1: =IF(F1="NA","Not Applicable",VLOOKUP(T1,'Maturity Rating'!G4:H8,2,FALSE)) -> Partial | F1: =IF(U1="NANANA","NA",AVERAGE(N4:N26)) -> 2.7732564 | T1: =ROUNDDOWN(F1,0) -> 2 | U1: =CONCATENATE(N4,N9,N20) -> 4.116666666666672.179292929292932.02380952380952
A3: S. No. | B3: High Level Description | C3: Control Description | D3: Identified Key Controls (K) | E3: Control | F3: Preventive/ Detective/Corrective | G3: Documentation | H3: Implementation | I3: Automation | J3: Monitor & Review | K3: Control Rating | L3: Rating with Key controls weightage | M3: Average Raiding | N3: Maturity Rating (1 - 5) | O3: Category | S3: Doc | T3: Impl | U3: Auto | V3: Review
A4: 3.1 | B4: Policy and procedures | C4: Asset Management policy should be established, documented and approved by authorized individuals. The document should be reviewed periodically and updated whenever significant changes occur. | D4: K | E4: Organization should have an Asset Management policy/ procedure defined, approved by the management | F4: Preventive | G4: Formally Documented | H4: 51 - 100% Implemented | I4: Automated | J4: Monitored & Reviewed | K4: =IF(W4="NANANANA",S4,IF(AND(OR(G4="Formally Documented",G4="Informally Documented"),H4="Not Implemented"),0.5*AVERAGE(S4:V4),AVERAGE(S4:V4))) -> 3 | L4: =IF(AND(D4="K",K4=1),'Maturity Rating'!$E$8,IF(K4="NA",K4,IF(D4="K",K4*'Maturity Rating'!$E$7,K4))) -> 3.6 | M4: =IF(X4="NANANANA",K4,AVERAGE(L4:L8)) -> 2.47 | N4: =IF(M4<1.1,1,IF(M4="NA",M4,(MIN(5,M4/3*5)))) -> 4.1166667 | O4: =IF(N4="NA",N4,VLOOKUP(Q4,'Maturity Rating'!G4:H8,2,FALSE)) -> Repeatable | Q4: =IF(N4="NA",N4,ROUNDDOWN(N4,0)) -> 4 | S4: =VLOOKUP(G4,'Maturity Rating'!A$2:B$5,2,FALSE) -> 3 | T4: =VLOOKUP(H4,'Maturity Rating'!A$8:B$11,2,FALSE) -> 3 | U4: =VLOOKUP(I4,'Maturity Rating'!A$14:B$17,2,FALSE) -> 3 | V4: =VLOOKUP(J4,'Maturity Rating'!A$20:B$23,2,FALSE) -> 3 | W4: =CONCATENATE(S4,T4,U4,V4) -> 3333 | X4: =CONCATENATE(L4,L5,L6,L7,L8) -> 3.632.252.51
A5: 3.2 | E5: Organization should have an Acceptable usage policy/ procedure defined, approved by the management | F5: Preventive | G5: Formally Documented | H5: 51 - 100% Implemented | I5: Automated | J5: Monitored & Reviewed | K5: =IF(W5="NANANANA",S5,IF(AND(OR(G5="Formally Documented",G5="Informally Documented"),H5="Not Implemented"),0.5*AVERAGE(S5:V5),AVERAGE(S5:V5))) -> 3 | L5: =IF(AND(D5="K",K5=1),'Maturity Rating'!$E$8,IF(K5="NA",K5,IF(D5="K",K5*'Maturity Rating'!$E$7,K5))) -> 3 | S5: =VLOOKUP(G5,'Maturity Rating'!A$2:B$5,2,FALSE) -> 3 | T5: =VLOOKUP(H5,'Maturity Rating'!A$8:B$11,2,FALSE) -> 3 | U5: =VLOOKUP(I5,'Maturity Rating'!A$14:B$17,2,FALSE) -> 3 | V5: =VLOOKUP(J5,'Maturity Rating'!A$20:B$23,2,FALSE) -> 3 | W5: =CONCATENATE(S5,T5,U5,V5) -> 3333
A6: 3.3 | E6: The documents are reviewed, updated and approved as per the defined frequency in the policy/ procedure. | F6: Preventive | G6: Formally Documented | H6: 0 - 50% Implemented | I6: Partially Automated | J6: Partially Monitored & Reviewed | K6: =IF(W6="NANANANA",S6,IF(AND(OR(G6="Formally Documented",G6="Informally Documented"),H6="Not Implemented"),0.5*AVERAGE(S6:V6),AVERAGE(S6:V6))) -> 2.25 | L6: =IF(AND(D6="K",K6=1),'Maturity Rating'!$E$8,IF(K6="NA",K6,IF(D6="K",K6*'Maturity Rating'!$E$7,K6))) -> 2.25 | S6: =VLOOKUP(G6,'Maturity Rating'!A$2:B$5,2,FALSE) -> 3 | T6: =VLOOKUP(H6,'Maturity Rating'!A$8:B$11,2,FALSE) -> 2 | U6: =VLOOKUP(I6,'Maturity Rating'!A$14:B$17,2,FALSE) -> 2 | V6: =VLOOKUP(J6,'Maturity Rating'!A$20:B$23,2,FALSE) -> 2 | W6: =CONCATENATE(S6,T6,U6,V6) -> 3222
A7: 3.4 | E7: The process of protecting media against unauthorized access, misuse or corruption, damage during transportation has been defined and implemented | F7: Preventive | G7: Formally Documented | H7: 0 - 50% Implemented | I7: Automated | J7: Partially Monitored & Reviewed | K7: =IF(W7="NANANANA",S7,IF(AND(OR(G7="Formally Documented",G7="Informally Documented"),H7="Not Implemented"),0.5*AVERAGE(S7:V7),AVERAGE(S7:V7))) -> 2.5 | L7: =IF(AND(D7="K",K7=1),'Maturity Rating'!$E$8,IF(K7="NA",K7,IF(D7="K",K7*'Maturity Rating'!$E$7,K7))) -> 2.5 | S7: =VLOOKUP(G7,'Maturity Rating'!A$2:B$5,2,FALSE) -> 3 | T7: =VLOOKUP(H7,'Maturity Rating'!A$8:B$11,2,FALSE) -> 2 | U7: =VLOOKUP(I7,'Maturity Rating'!A$14:B$17,2,FALSE) -> 3 | V7: =VLOOKUP(J7,'Maturity Rating'!A$20:B$23,2,FALSE) -> 2 | W7: =CONCATENATE(S7,T7,U7,V7) -> 3232
A8: 3.5 | E8: The version control of the documents should be maintained | F8: Preventive | G8: Not Documented | H8: Not Implemented | I8: Not Applicable | J8: Not Applicable | K8: =IF(W8="NANANANA",S8,IF(AND(OR(G8="Formally Documented",G8="Informally Documented"),H8="Not Implemented"),0.5*AVERAGE(S8:V8),AVERAGE(S8:V8))) -> 1 | L8: =IF(AND(D8="K",K8=1),'Maturity Rating'!$E$8,IF(K8="NA",K8,IF(D8="K",K8*'Maturity Rating'!$E$7,K8))) -> 1 | S8: =VLOOKUP(G8,'Maturity Rating'!A$2:B$5,2,FALSE) -> 1 | T8: =VLOOKUP(H8,'Maturity Rating'!A$8:B$11,2,FALSE) -> 1 | U8: =VLOOKUP(I8,'Maturity Rating'!A$14:B$17,2,FALSE) -> NA | V8: =VLOOKUP(J8,'Maturity Rating'!A$20:B$23,2,FALSE) -> NA | W8: =CONCATENATE(S8,T8,U8,V8) -> 11NANA
A9: 3.6 | B9: Inventory of Assets | C9: Ensure that all the organizational assets are identified, classified and appropriate level of protection in accordance with its importance to the organization are defined. | E9: There is a centralized configuration management system to manage the assets. | F9: Detective | G9: Not Documented | H9: Not Implemented | I9: Not Automated | J9: Not Monitored & Reviewed | K9: =IF(W9="NANANANA",S9,IF(AND(OR(G9="Formally Documented",G9="Informally Documented"),H9="Not Implemented"),0.5*AVERAGE(S9:V9),AVERAGE(S9:V9))) -> 1 | L9: =IF(AND(D9="K",K9=1),'Maturity Rating'!$E$8,IF(K9="NA",K9,IF(D9="K",K9*'Maturity Rating'!$E$7,K9))) -> 1 | M9: =IF(X9="NANANANA",K9,AVERAGE(L9:L19)) -> 1.3075758 | N9: =IF(M9<1.1,1,IF(M9="NA",M9,(MIN(5,M9/3*5)))) -> 2.1792929 | O9: =IF(N9="NA",N9,VLOOKUP(Q9,'Maturity Rating'!G4:H8,2,FALSE)) -> Partial | Q9: =IF(N9="NA",N9,ROUNDDOWN(N9,0)) -> 2 | S9: =VLOOKUP(G9,'Maturity Rating'!A$2:B$5,2,FALSE) -> 1 | T9: =VLOOKUP(H9,'Maturity Rating'!A$8:B$11,2,FALSE) -> 1 | U9: =VLOOKUP(I9,'Maturity Rating'!A$14:B$17,2,FALSE) -> 1 | V9: =VLOOKUP(J9,'Maturity Rating'!A$20:B$23,2,FALSE) -> 1 | W9: =CONCATENATE(S9,T9,U9,V9) -> 1111 | X9: =CONCATENATE(L9,L10,L11,L12,L13,L14,L15,L16,L17,L18,L19) -> 10.7511.333333333333331.81.251.2511.251.252.5
A10: 3.7 | D10: K | E10: All physical devices, systems, software platforms and applications within the organization are inventoried. | F10: Detective | G10: Informally Documented | H10: Not Implemented | I10: Not Automated | J10: Not Monitored & Reviewed | K10: =IF(W10="NANANANA",S10,IF(AND(OR(G10="Formally Documented",G10="Informally Documented"),H10="Not Implemented"),0.5*AVERAGE(S10:V10),AVERAGE(S10:V10))) -> 0.625 | L10: =IF(AND(D10="K",K10=1),'Maturity Rating'!$E$8,IF(K10="NA",K10,IF(D10="K",K10*'Maturity Rating'!$E$7,K10))) -> 0.75 | S10: =VLOOKUP(G10,'Maturity Rating'!A$2:B$5,2,FALSE) -> 2 | T10: =VLOOKUP(H10,'Maturity Rating'!A$8:B$11,2,FALSE) -> 1 | U10: =VLOOKUP(I10,'Maturity Rating'!A$14:B$17,2,FALSE) -> 1 | V10: =VLOOKUP(J10,'Maturity Rating'!A$20:B$23,2,FALSE) -> 1 | W10: =CONCATENATE(S10,T10,U10,V10) -> 2111
A11: 3.8 | E11: All new assets procured must be approved by an authorized individual. | F11: Preventive | G11: Not Documented | H11: Not Implemented | I11: Not Automated | J11: Not Monitored & Reviewed | K11: =IF(W11="NANANANA",S11,IF(AND(OR(G11="Formally Documented",G11="Informally Documented"),H11="Not Implemented"),0.5*AVERAGE(S11:V11),AVERAGE(S11:V11))) -> 1 | L11: =IF(AND(D11="K",K11=1),'Maturity Rating'!$E$8,IF(K11="NA",K11,IF(D11="K",K11*'Maturity Rating'!$E$7,K11))) -> 1 | S11: =VLOOKUP(G11,'Maturity Rating'!A$2:B$5,2,FALSE) -> 1 | T11: =VLOOKUP(H11,'Maturity Rating'!A$8:B$11,2,FALSE) -> 1 | U11: =VLOOKUP(I11,'Maturity Rating'!A$14:B$17,2,FALSE) -> 1 | V11: =VLOOKUP(J11,'Maturity Rating'!A$20:B$23,2,FALSE) -> 1 | W11: =CONCATENATE(S11,T11,U11,V11) -> 1111
A12: 3.9 | E12: All assets follow the defined asset labelling nomenclature. | F12: Detective | G12: Not Documented | H12: 0 - 50% Implemented | I12: Not Applicable | J12: Not Monitored & Reviewed | K12: =IF(W12="NANANANA",S12,IF(AND(OR(G12="Formally Documented",G12="Informally Documented"),H12="Not Implemented"),0.5*AVERAGE(S12:V12),AVERAGE(S12:V12))) -> 1.3333333 | L12: =IF(AND(D12="K",K12=1),'Maturity Rating'!$E$8,IF(K12="NA",K12,IF(D12="K",K12*'Maturity Rating'!$E$7,K12))) -> 1.3333333 | S12: =VLOOKUP(G12,'Maturity Rating'!A$2:B$5,2,FALSE) -> 1 | T12: =VLOOKUP(H12,'Maturity Rating'!A$8:B$11,2,FALSE) -> 2 | U12: =VLOOKUP(I12,'Maturity Rating'!A$14:B$17,2,FALSE) -> NA | V12: =VLOOKUP(J12,'Maturity Rating'!A$20:B$23,2,FALSE) -> 1 | W12: =CONCATENATE(S12,T12,U12,V12) -> 12NA1
